Workbook

Sheet README
A1: I4C Integration – Simulated Demo Dataset (for Bank Workflow Walkthrough)
A3: How to use
A4: This workbook contains synthetic (non-customer) data shaped to match the NIC/I4C payload fields in the provided API documentation.
A5: Use it to simulate the end-to-end flow: I4C pushes Fraud Reports → Bank ACKs & creates cases → Bank attempts hold/negative lien → Bank sends FraudReportStatusUpdate → I4C responds.
A7: Primary keys to join sheets:
A8: • acknowledgement_no: unique fraud report reference generated by I4C.
A9: • job_id: unique bank-side tracking id returned to I4C at ACK time.
A10: • request_id: unique Bank → I4C status-update request identifier (demo convenience).
A11: • incident_id and root_rrn_transaction_id (RRN): transaction-level identifiers.
A13: Suggested demo order:
A14: 1) Open 'I4C_Inbound_FraudReports' and pick an acknowledgement_no.
A15: 2) Drill into 'I4C_Incidents' for incident-level details and Layer.
... A19: 6) View 'I4C_StatusUpdate_Response' and 'Workflow_Timeline' for SLA/TAT storyboards.

Sheet I4C_Inbound_FraudReports
A1: acknowledgement_no | B1: sub_category | C1: requestor | D1: payer_bank | E1: payer_bank_code | F1: mode_of_payment | G1: payer_mobile_number | H1: payer_account_number | I1: state | J1: district | K1: transaction_type | L1: wallet | M1: received_at | N1: incident_count | O1: total_disputed_amount | P1: bank_ack_response_code | Q1: bank_job_id | R1: calc_total_disputed_amount | S1: amount_match_flag
A2: 31608230000001 | B2: UPI Related Frauds | C2: I4C-MHA | D2: Bank of Baroda | E2: 6 | F2: UPI | G2: 0097882081 | H2: LEEPZHPCF07UQN | I2: TAMIL NADU | J2: Chennai | K2: Non Mandatory | L2: Google Pay | M2: 45944.267 | N2: 2 | O2: 1285.27 | P2: 00 | Q2: a809e351-37a8-4017-9977-dc4d0e60ec7b | R2: =SUMIF(I4C_Incidents!$A:$A,$A2,I4C_Incidents!$H:$H) | S2: =IF(ABS($O2-$R2)<0.01,"OK","CHECK")
A3: 31608230000002 | B3: Business Email Compromise/Email Takeover | C3: I4C-MHA | D3: ICICI Bank | E3: 3 | F3: Debit/Credit | G3: 3036541458 | H3: Z8VBHQLQCG1WU1 | I3: MAHARASHTRA | J3: Pune | K3: Mandatory | M3: 45950.073 | N3: 3 | O3: 600.98 | P3: 00 | Q3: dc8ac3a9-c97b-4688-a12b-989696a01ca5 | R3: =SUMIF(I4C_Incidents!$A:$A,$A3,I4C_Incidents!$H:$H) | S3: =IF(ABS($O3-$R3)<0.01,"OK","CHECK")
A4: 31608230000003 | B4: UPI Related Frauds | C4: I4C-MHA | D4: Axis Bank | E4: 4 | F4: IMPS | G4: 4529912419 | H4: BTYZMEPGTHCW81 | I4: TAMIL NADU | J4: Chennai | K4: Mandatory | L4: PhonePe | M4: 45955.934 | N4: 2 | O4: 11250.68 | P4: 00 | Q4: a7cd9031-8026-4865-a5bf-503cb85d456b | R4: =SUMIF(I4C_Incidents!$A:$A,$A4,I4C_Incidents!$H:$H) | S4: =IF(ABS($O4-$R4)<0.01,"OK","CHECK")
A5: 31608230000004 | B5: UPI Related Frauds | C5: I4C-MHA | D5: Punjab National Bank | E5: 5 | F5: IMPS | G5: 1334123281 | H5: KA024SCOSS3EOQ | I5: KARNATAKA | J5: Bengaluru Urban | K5: Mandatory | L5: BHIM | M5: 45936.944 | N5: 3 | O5: 5750.49 | P5: 00 | Q5: 260f5953-5ef8-4b0a-9ad0-aa82d14417c5 | R5: =SUMIF(I4C_Incidents!$A:$A,$A5,I4C_Incidents!$H:$H) | S5: =IF(ABS($O5-$R5)<0.01,"OK","CHECK")
A6: 31608230000005 | B6: Business Email Compromise/Email Takeover | C6: I4C-MHA | D6: ICICI Bank | E6: 3 | F6: IMPS | G6: 7809134316 | H6: GG2KTBCUDSWX1J | I6: KARNATAKA | J6: Bengaluru Urban | K6: Mandatory | M6: 45957.16 | N6: 2 | O6: 10500.44 | P6: 00 | Q6: b84e9000-babf-4700-b34e-ccc2ca1554ce | R6: =SUMIF(I4C_Incidents!$A:$A,$A6,I4C_Incidents!$H:$H) | S6: =IF(ABS($O6-$R6)<0.01,"OK","CHECK")
A7: 31608230000006 | B7: Business Email Compromise/Email Takeover | C7: I4C-MHA | D7: Bank of Baroda | E7: 6 | F7: Debit/Credit | G7: 7964053773 | H7: XGX8WDZRMH3FNB | I7: DELHI | J7: South Delhi | K7: Mandatory | M7: 45947.562 | N7: 1 | O7: 250.86 | P7: 00 | Q7: 87ad8bc0-8306-4d41-95e4-f3591d26c43f | R7: =SUMIF(I4C_Incidents!$A:$A,$A7,I4C_Incidents!$H:$H) | S7: =IF(ABS($O7-$R7)<0.01,"OK","CHECK")
A8: 31608230000007 | B8: UPI Related Frauds | C8: I4C-MHA | D8: State Bank of India | E8: 1 | F8: UPI | G8: 9212499856 | H8: 7S361GH9N12O0V | I8: UTTAR PRADESH | J8: Lucknow | K8: Non Mandatory | L8: BHIM | M8: 45951.566 | N8: 1 | O8: 4999.74 | P8: 00 | Q8: 0797d398-04e1-458f-a273-42c1b0a09584 | R8: =SUMIF(I4C_Incidents!$A:$A,$A8,I4C_Incidents!$H:$H) | S8: =IF(ABS($O8-$R8)<0.01,"OK","CHECK")
A9: 31608230000008 | B9: Business Email Compromise/Email Takeover | C9: I4C-MHA | D9: State Bank of India | E9: 1 | F9: Debit/Credit | G9: 2961201836 | H9: 03VKXTUFDJKDFR | I9: UTTAR PRADESH | J9: Lucknow | K9: Mandatory | M9: 45951.958 | N9: 2 | O9: 1751.38 | P9: 00 | Q9: 382fbbbe-527b-4d04-ae9f-ca5e0427223c | R9: =SUMIF(I4C_Incidents!$A:$A,$A9,I4C_Incidents!$H:$H) | S9: =IF(ABS($O9-$R9)<0.01,"OK","CHECK")
A10: 31608230000009 | B10: UPI Related Frauds | C10: I4C-MHA | D10: Axis Bank | E10: 4 | F10: IMPS | G10: 3597820715 | H10: F6LCP2277KXXSY | I10: WEST BENGAL | J10: Kolkata | K10: Non Mandatory | L10: Paytm | M10: 45960.399 | N10: 1 | O10: 4999.14 | P10: 00 | Q10: 8ebca7ef-f7dc-40cd-a99e-7537d57a4b40 | R10: =SUMIF(I4C_Incidents!$A:$A,$A10,I4C_Incidents!$H:$H) | S10: =IF(ABS($O10-$R10)<0.01,"OK","CHECK")
A11: 31608230000010 | B11: Business Email Compromise/Email Takeover | C11: I4C-MHA | D11: Central Bank of India | E11: 10 | F11: UPI | G11: 8862392407 | H11: X9G7HSFKR26J1F | I11: KARNATAKA | J11: Bengaluru Urban | K11: Non Mandatory | L11: BHIM | M11: 45948.344 | N11: 1 | O11: 9999.71 | P11: 00 | Q11: 7ccbb3c8-ddb8-415f-9d43-4be9e9a11433 | R11: =SUMIF(I4C_Incidents!$A:$A,$A11,I4C_Incidents!$H:$H) | S11: =IF(ABS($O11-$R11)<0.01,"OK","CHECK")
A12: 31608230000011 | B12: UPI Related Frauds | C12: I4C-MHA | D12: Axis Bank | E12: 4 | F12: UPI | G12: 0654051531 | H12: VICW8VL34LIE3C | I12: TELANGANA | J12: Hyderabad | K12: Non Mandatory | L12: Google Pay | M12: 45933.5 | N12: 1 | O12: 9999.66 | P12: 00 | Q12: f2a9ed34-112d-43e1-99ae-06af4acc27ef | R12: =SUMIF(I4C_Incidents!$A:$A,$A12,I4C_Incidents!$H:$H) | S12: =IF(ABS($O12-$R12)<0.01,"OK","CHECK")
A13: 31608230000012 | B13: UPI Related Frauds | C13: I4C-MHA | D13: Punjab National Bank | E13: 5 | F13: UPI | G13: 6543102786 | H13: 9HQQ2NS5MHIE2L | I13: UTTAR PRADESH | J13: Lucknow | K13: Mandatory | L13: PhonePe | M13: 45946.889 | N13: 2 | O13: 198.95 | P13: 00 | Q13: fb1b1cf6-96ac-46a4-84ac-3eacc39b2bd8 | R13: =SUMIF(I4C_Incidents!$A:$A,$A13,I4C_Incidents!$H:$H) | S13: =IF(ABS($O13-$R13)<0.01,"OK","CHECK")
A14: 31608230000013 | B14: Business Email Compromise/Email Takeover | C14: I4C-MHA | D14: Axis Bank | E14: 4 | F14: IMPS | G14: 6325953278 | H14: 35T5BFZ63PNWDD | I14: TELANGANA | J14: Hyderabad | K14: Mandatory | M14: 45955.399 | N14: 3 | O14: 234.72 | P14: 00 | Q14: 17c42136-f082-48bc-b610-0672d0d42072 | R14: =SUMIF(I4C_Incidents!$A:$A,$A14,I4C_Incidents!$H:$H) | S14: =IF(ABS($O14-$R14)<0.01,"OK","CHECK")
A15: 31608230000014 | B15: Business Email Compromise/Email Takeover | C15: I4C-MHA | D15: Axis Bank | E15: 4 | F15: UPI | G15: 2404157473 | H15: M8R9RIGPPD7OOD | I15: MAHARASHTRA | J15: Pune | K15: Non Mandatory | L15: BHIM | M15: 45947.406 | N15: 2 | O15: 19998.39 | P15: 00 | Q15: 85909e1c-12aa-470f-981c-2741dccddf7f | R15: =SUMIF(I4C_Incidents!$A:$A,$A15,I4C_Incidents!$H:$H) | S15: =IF(ABS($O15-$R15)<0.01,"OK","CHECK")
A16: 31608230000015 | B16: Business Email Compromise/Email Takeover | C16: I4C-MHA | D16: HDFC Bank | E16: 2 | F16: UPI | G16: 8414593327 | H16: J3X0948NPF727X | I16: MAHARASHTRA | J16: Pune | K16: Non Mandatory | L16: Amazon Pay | M16: 45936.819 | N16: 1 | O16: 500.09 | P16: 00 | Q16: e1bf6439-b35d-4699-8f1a-9e23440e90aa | R16: =SUMIF(I4C_Incidents!$A:$A,$A16,I4C_Incidents!$H:$H) | S16: =IF(ABS($O16-$R16)<0.01,"OK","CHECK")
A17: 31608230000016 | B17: Business Email Compromise/Email Takeover | C17: I4C-MHA | D17: Bank of Baroda | E17: 6 | F17: IMPS | G17: 8686337524 | H17: MHC0BPNEGC2DPC | I17: WEST BENGAL | J17: Kolkata | K17: Non Mandatory | M17: 45952.684 | N17: 1 | O17: 250.88 | P17: 00 | Q17: 79a28af4-62f8-4124-bbf2-32c6e9d92329 | R17: =SUMIF(I4C_Incidents!$A:$A,$A17,I4C_Incidents!$H:$H) | S17: =IF(ABS($O17-$R17)<0.01,"OK","CHECK")
A18: 31608230000017 | B18: Business Email Compromise/Email Takeover | C18: I4C-MHA | D18: State Bank of India | E18: 1 | F18: Debit/Credit | G18: 3173936385 | H18: SY38WTQX653G4U | I18: KARNATAKA | J18: Bengaluru Urban | K18: Non Mandatory | M18: 45949.368 | N18: 2 | O18: 5099 | P18: 00 | Q18: 8f9d0193-d0ef-4ff0-8143-60e737c9760e | R18: =SUMIF(I4C_Incidents!$A:$A,$A18,I4C_Incidents!$H:$H) | S18: =IF(ABS($O18-$R18)<0.01,"OK","CHECK")
A19: 31608230000018 | B19: Business Email Compromise/Email Takeover | C19: I4C-MHA | D19: Axis Bank | E19: 4 | F19: Debit/Credit | G19: 5866296194 | H19: PEFRJYJYUXGFAT | I19: UTTAR PRADESH | J19: Lucknow | K19: Mandatory | M19: 45948.847 | N19: 2 | O19: 350.01 | P19: 00 | Q19: a392623d-7711-4020-a2c9-793555384b0b | R19: =SUMIF(I4C_Incidents!$A:$A,$A19,I4C_Incidents!$H:$H) | S19: =IF(ABS($O19-$R19)<0.01,"OK","CHECK")
A20: 31608230000019 | B20: UPI Related Frauds | C20: I4C-MHA | D20: Punjab National Bank | E20: 5 | F20: IMPS | G20: 6561014388 | H20: 9O2XZ36JWB4GS0 | I20: MAHARASHTRA | J20: Pune | K20: Mandatory | L20: PhonePe | M20: 45938.25 | N20: 2 | O20: 349.41 | P20: 00 | Q20: 5c2cbf12-f130-47b1-a973-31250ad54c30 | R20: =SUMIF(I4C_Incidents!$A:$A,$A20,I4C_Incidents!$H:$H) | S20: =IF(ABS($O20-$R20)<0.01,"OK","CHECK")
A21: 31608230000020 | B21: UPI Related Frauds | C21: I4C-MHA | D21: Axis Bank | E21: 4 | F21: Debit/Credit | G21: 3688767677 | H21: KFBOSCRO8SK359 | I21: MAHARASHTRA | J21: Pune | K21: Mandatory | L21: Amazon Pay | M21: 45936.917 | N21: 2 | O21: 350.06 | P21: 00 | Q21: 847dbb0e-b66b-41c0-b403-75ca9ecdc286 | R21: =SUMIF(I4C_Incidents!$A:$A,$A21,I4C_Incidents!$H:$H) | S21: =IF(ABS($O21-$R21)<0.01,"OK","CHECK")
A22: 31608230000021 | B22: Business Email Compromise/Email Takeover | C22: I4C-MHA | D22: State Bank of India | E22: 1 | F22: IMPS | G22: 5415206436 | H22: FGAN4EIO72AAVH | I22: WEST BENGAL | J22: Kolkata | K22: Non Mandatory | M22: 45937.788 | N22: 2 | O22: 135.28 | P22: 00 | Q22: cc2c80ef-e1cd-4a3f-a6fe-9aad3850ab1b | R22: =SUMIF(I4C_Incidents!$A:$A,$A22,I4C_Incidents!$H:$H) | S22: =IF(ABS($O22-$R22)<0.01,"OK","CHECK")
A23: 31608230000022 | B23: Business Email Compromise/Email Takeover | C23: I4C-MHA | D23: Bank of Baroda | E23: 6 | F23: UPI | G23: 3031617990 | H23: TLHAIAK5W77QKX | I23: GUJARAT | J23: Surat | K23: Mandatory | L23: Paytm | M23: 45937.104 | N23: 1 | O23: 500.86 | P23: 00 | Q23: c448c5ea-5f48-4c6a-bd8f-92d098983753 | R23: =SUMIF(I4C_Incidents!$A:$A,$A23,I4C_Incidents!$H:$H) | S23: =IF(ABS($O23-$R23)<0.01,"OK","CHECK")
A24: 31608230000023 | B24: Business Email Compromise/Email Takeover | C24: I4C-MHA | D24: State Bank of India | E24: 1 | F24: IMPS | G24: 0238061744 | H24: UF93AXMSTP3X5M | I24: KARNATAKA | J24: Bengaluru Urban | K24: Mandatory | M24: 45938.684 | N24: 1 | O24: 99.42 | P24: 00 | Q24: cf64d3e6-8e1a-4394-9bf7-a06993c80807 | R24: =SUMIF(I4C_Incidents!$A:$A,$A24,I4C_Incidents!$H:$H) | S24: =IF(ABS($O24-$R24)<0.01,"OK","CHECK")
A25: 31608230000024 | B25: Business Email Compromise/Email Takeover | C25: I4C-MHA | D25: State Bank of India | E25: 1 | F25: IMPS | G25: 5374741124 | H25: CNUJFPWZ6DTQLB | I25: WEST BENGAL | J25: Kolkata | K25: Non Mandatory | M25: 45953.326 | N25: 3 | O25: 15249.57 | P25: 00 | Q25: fd508175-47e4-4db9-9acc-f5b2c60a8ea5 | R25: =SUMIF(I4C_Incidents!$A:$A,$A25,I4C_Incidents!$H:$H) | S25: =IF(ABS($O25-$R25)<0.01,"OK","CHECK")
A26: 31608230000025 | B26: Business Email Compromise/Email Takeover | C26: I4C-MHA | D26: State Bank of India | E26: 1 | F26: UPI | G26: 6915452267 | H26: UL9WOLYTSILAZC | I26: GUJARAT | J26: Surat | K26: Mandatory | L26: Amazon Pay | M26: 45946.819 | N26: 3 | O26: 5598.19 | P26: 00 | Q26: e6020150-28c4-4133-b8bf-8b84494d3c11 | R26: =SUMIF(I4C_Incidents!$A:$A,$A26,I4C_Incidents!$H:$H) | S26: =IF(ABS($O26-$R26)<0.01,"OK","CHECK")
A27: 31608230000026 | B27: Business Email Compromise/Email Takeover | C27: I4C-MHA | D27: State Bank of India | E27: 1 | F27: IMPS | G27: 6329451168 | H27: Z9UR73A70H0JJG | I27: MAHARASHTRA | J27: Pune | K27: Mandatory | M27: 45958.688 | N27: 1 | O27: 500.14 | P27: 00 | Q27: 0c3b8a7e-84e0-4bf7-90b1-90943ee41090 | R27: =SUMIF(I4C_Incidents!$A:$A,$A27,I4C_Incidents!$H:$H) | S27: =IF(ABS($O27-$R27)<0.01,"OK","CHECK")
A28: 31608230000027 | B28: Business Email Compromise/Email Takeover | C28: I4C-MHA | D28: HDFC Bank | E28: 2 | F28: UPI | G28: 9855241406 | H28: DKNOONR06BA4IL | I28: DELHI | J28: South Delhi | K28: Mandatory | L28: Google Pay | M28: 45943.625 | N28: 3 | O28: 6285.75 | P28: 00 | Q28: 4ad56b6f-7e0f-4744-a89a-aed047152451 | R28: =SUMIF(I4C_Incidents!$A:$A,$A28,I4C_Incidents!$H:$H) | S28: =IF(ABS($O28-$R28)<0.01,"OK","CHECK")
A29: 31608230000028 | B29: UPI Related Frauds | C29: I4C-MHA | D29: Bank of Baroda | E29: 6 | F29: Debit/Credit | G29: 6761847230 | H29: T0G7RI0G6HSHG5 | I29: KARNATAKA | J29: Bengaluru Urban | K29: Mandatory | L29: Amazon Pay | M29: 45941.069 | N29: 2 | O29: 285.82 | P29: 00 | Q29: e15f19c7-2369-41e3-a3b6-5ec3f50b7c2f | R29: =SUMIF(I4C_Incidents!$A:$A,$A29,I4C_Incidents!$H:$H) | S29: =IF(ABS($O29-$R29)<0.01,"OK","CHECK")
A30: 31608230000029 | B30: UPI Related Frauds | C30: I4C-MHA | D30: State Bank of India | E30: 1 | F30: IMPS | G30: 2877217535 | H30: RD6O9YZPF322F5 | I30: UTTAR PRADESH | J30: Lucknow | K30: Non Mandatory | L30: Paytm | M30: 45937.135 | N30: 2 | O30: 11249.6 | P30: 00 | Q30: 47f45dd2-b53d-45e3-8eed-29c832f5cb8b | R30: =SUMIF(I4C_Incidents!$A:$A,$A30,I4C_Incidents!$H:$H) | S30: =IF(ABS($O30-$R30)<0.01,"OK","CHECK")
A31: 31608230000030 | B31: UPI Related Frauds | C31: I4C-MHA | D31: Punjab National Bank | E31: 5 | F31: IMPS | G31: 8386384066 | H31: 0U9DAQM2OX8MMS | I31: UTTAR PRADESH | J31: Lucknow | K31: Mandatory | L31: Google Pay | M31: 45934.99 | N31: 1 | O31: 35.33 | P31: 00 | Q31: 38c47fb7-350b-4e16-bd31-1c77d36f369d | R31: =SUMIF(I4C_Incidents!$A:$A,$A31,I4C_Incidents!$H:$H) | S31: =IF(ABS($O31-$R31)<0.01,"OK","CHECK")

Sheet I4C_Incidents
A1: acknowledgement_no | B1: incident_id | C1: sub_category | D1: amount | E1: rrn | F1: transaction_date | G1: transaction_time | H1: disputed_amount | I1: layer | J1: payee_bank | K1: payee_bank_code | L1: payee_ifsc_code | M1: payee_account_number
A2: 31608230000001 | B2: INC-0001-01 | C2: UPI Related Frauds | D2: 1250.27 | E2: 2475107991183 | F2: 2025-10-14 | G2: 02:35:00 | H2: 1250.27 | I2: 1 | J2: Yes Bank | K2: 8 | L2: YESB0354278 | M2: 49808412411824
A3: 31608230000001 | B3: INC-0001-02 | C3: UPI Related Frauds | D3: 35 | E3: 4935348740164 | F3: 2025-10-14 | G3: 03:37:00 | H3: 35 | I3: 0 | J3: Canara Bank | K3: 12 | L3: CNRB0278680 | M3: 11280598262045
A4: 31608230000002 | B4: INC-0002-01 | C4: Business Email Compromise/Email Takeover | D4: 250.66 | E4: 3406088356159 | F4: 2025-10-19 | G4: 22:36:00 | H4: 250.66 | I4: 0 | J4: Canara Bank | K4: 12 | L4: CNRB0846564 | M4: 82366299468044
A5: 31608230000002 | B5: INC-0002-02 | C5: Business Email Compromise/Email Takeover | D5: 250.52 | E5: 3699577738721 | F5: 2025-10-19 | G5: 23:02:00 | H5: 250.52 | I5: 2 | J5: Union Bank of India | K5: 13 | L5: UBIN0134332 | M5: 00379176936763
A6: 31608230000002 | B6: INC-0002-03 | C6: Business Email Compromise/Email Takeover | D6: 99.8 | E6: 2016328708317 | F6: 2025-10-19 | G6: 23:25:00 | H6: 99.8 | I6: 2 | J6: Union Bank of India | K6: 13 | L6: UBIN0798687 | M6: 27743487347143
A7: 31608230000003 | B7: INC-0003-01 | C7: UPI Related Frauds | D7: 9999.92 | E7: 0671657262849 | F7: 2025-10-25 | G7: 20:21:00 | H7: 9999.92 | I7: 1 | J7: UCO Bank | K7: 14 | L7: UCBA0945314 | M7: 73799650752735
A8: 31608230000003 | B8: INC-0003-02 | C8: UPI Related Frauds | D8: 1250.76 | E8: 4549480831367 | F8: 2025-10-25 | G8: 20:19:00 | H8: 1250.76 | I8: 2 | J8: Varachha Co-operative Bank | K8: 36 | L8: VARA0701436 | M8: 34957885685574
A9: 31608230000004 | B9: INC-0004-01 | C9: UPI Related Frauds | D9: 500.69 | E9: 3242102499471 | F9: 2025-10-06 | G9: 20:52:00 | H9: 500.69 | I9: 2 | J9: Canara Bank | K9: 12 | L9: CNRB0887719 | M9: 06594013990490
A10: 31608230000004 | B10: INC-0004-02 | C10: UPI Related Frauds | D10: 250.32 | E10: 2787429671756 | F10: 2025-10-06 | G10: 18:56:00 | H10: 250.32 | I10: 0 | J10: IndusInd Bank | K10: 9 | L10: INDB0567468 | M10: 07154516808760
A11: 31608230000004 | B11: INC-0004-03 | C11: UPI Related Frauds | D11: 4999.48 | E11: 3859770348247 | F11: 2025-10-06 | G11: 19:54:00 | H11: 4999.48 | I11: 0 | J11: IDFC FIRST Bank | K11: 11 | L11: IDFB0248086 | M11: 13171274846773
A12: 31608230000005 | B12: INC-0005-01 | C12: Business Email Compromise/Email Takeover | D12: 500.64 | E12: 9222196937923 | F12: 2025-10-27 | G12: 02:40:00 | H12: 500.64 | I12: 1 | J12: Kotak Mahindra Bank | K12: 7 | L12: KKBK0748217 | M12: 59464743671369
A13: 31608230000005 | B13: INC-0005-02 | C13: Business Email Compromise/Email Takeover | D13: 9999.8 | E13: 5944064090974 | F13: 2025-10-27 | G13: 02:49:00 | H13: 9999.8 | I13: 1 | J13: IDFC FIRST Bank | K13: 11 | L13: IDFB0942104 | M13: 70952145623285
... A56: 31608230000030 | B56: INC-0030-01 | C56: UPI Related Frauds | D56: 35.33 | E56: 2816064842294 | F56: 2025-10-04 | G56: 23:30:00 | H56: 35.33 | I56: 0 | J56: IndusInd Bank | K56: 9 | L56: INDB0590947 | M56: 98515832818268

Sheet Bank_Case_Workflow
A1: case_id | B1: acknowledgement_no | C1: job_id | D1: created_at | E1: assigned_queue | F1: assigned_branch_id | G1: priority | H1: current_state | I1: scenario
A2: I4C-CASE-2025-0001 | B2: 31608230000001 | C2: a809e351-37a8-4017-9977-dc4d0e60ec7b | D2: 45944.267 | E2: BRANCH_OPS | F2: BR-006 | G2: P3-MEDIUM | H2: RECEIVED | I2: NEGATIVE_LIEN
A3: I4C-CASE-2025-0002 | B3: 31608230000002 | C3: dc8ac3a9-c97b-4688-a12b-989696a01ca5 | D3: 45950.073 | E3: DIGITAL_CHANNELS | F3: BR-006 | G3: P3-MEDIUM | H3: RECEIVED | I3: HOLD_PLACED
A4: I4C-CASE-2025-0003 | B4: 31608230000003 | C4: a7cd9031-8026-4865-a5bf-503cb85d456b | D4: 45955.934 | E4: BRANCH_OPS | F4: BR-005 | G4: P1-CRITICAL | H4: RECEIVED | I4: HOLD_PLACED
A5: I4C-CASE-2025-0004 | B5: 31608230000004 | C5: 260f5953-5ef8-4b0a-9ad0-aa82d14417c5 | D5: 45936.945 | E5: BRANCH_OPS | F5: BR-009 | G5: P2-HIGH | H5: RECEIVED | I5: PARTIAL_HOLD
A6: I4C-CASE-2025-0005 | B6: 31608230000005 | C6: b84e9000-babf-4700-b34e-ccc2ca1554ce | D6: 45957.16 | E6: DIGITAL_CHANNELS | F6: BR-003 | G6: P2-HIGH | H6: RECEIVED | I6: ACCOUNT_NOT_FOUND
A7: I4C-CASE-2025-0006 | B7: 31608230000006 | C7: 87ad8bc0-8306-4d41-95e4-f3591d26c43f | D7: 45947.563 | E7: HO_FRAUD_DESK | F7: BR-009 | G7: P2-HIGH | H7: RECEIVED | I7: HOLD_PLACED
A8: I4C-CASE-2025-0007 | B8: 31608230000007 | C8: 0797d398-04e1-458f-a273-42c1b0a09584 | D8: 45951.566 | E8: DIGITAL_CHANNELS | F8: BR-006 | G8: P1-CRITICAL | H8: RECEIVED | I8: HOLD_PLACED
A9: I4C-CASE-2025-0008 | B9: 31608230000008 | C9: 382fbbbe-527b-4d04-ae9f-ca5e0427223c | D9: 45951.958 | E9: HO_FRAUD_DESK | F9: BR-003 | G9: P3-MEDIUM | H9: RECEIVED | I9: HOLD_PLACED
A10: I4C-CASE-2025-0009 | B10: 31608230000009 | C10: 8ebca7ef-f7dc-40cd-a99e-7537d57a4b40 | D10: 45960.399 | E10: BRANCH_OPS | F10: BR-004 | G10: P1-CRITICAL | H10: RECEIVED | I10: HOLD_PLACED
A11: I4C-CASE-2025-0010 | B11: 31608230000010 | C11: 7ccbb3c8-ddb8-415f-9d43-4be9e9a11433 | D11: 45948.344 | E11: HO_FRAUD_DESK | F11: BR-005 | G11: P1-CRITICAL | H11: RECEIVED | I11: NEGATIVE_LIEN
A12: I4C-CASE-2025-0011 | B12: 31608230000011 | C12: f2a9ed34-112d-43e1-99ae-06af4acc27ef | D12: 45933.5 | E12: DIGITAL_CHANNELS | F12: BR-002 | G12: P3-MEDIUM | H12: RECEIVED | I12: HOLD_PLACED
A13: I4C-CASE-2025-0012 | B13: 31608230000012 | C13: fb1b1cf6-96ac-46a4-84ac-3eacc39b2bd8 | D13: 45946.889 | E13: HO_FRAUD_DESK | F13: BR-010 | G13: P1-CRITICAL | H13: RECEIVED | I13: PARTIAL_HOLD
... A31: I4C-CASE-2025-0030 | B31: 31608230000030 | C31: 38c47fb7-350b-4e16-bd31-1c77d36f369d | D31: 45934.99 | E31: DIGITAL_CHANNELS | F31: BR-002 | G31: P1-CRITICAL | H31: RECEIVED | I31: ACCOUNT_NOT_FOUND

Sheet Bank_Hold_Actions
A1: action_id | B1: case_id | C1: acknowledgement_no | D1: incident_id | E1: action_type | F1: action_time | G1: requested_amount | H1: action_amount | I1: held_amount | J1: hold_reference | K1: negative_lien_flag | L1: outcome | M1: remarks
A2: ACT-0001-01 | B2: I4C-CASE-2025-0001 | C2: 31608230000001 | D2: INC-0001-01 | E2: NEGATIVE_LIEN | F2: 45944.275 | G2: 1250.27 | H2: 0 | I2: 0 | K2: Y | L2: SUCCESS | M2: Balance not available; negative lien marked
A3: ACT-0001-02 | B3: I4C-CASE-2025-0001 | C3: 31608230000001 | D3: INC-0001-02 | E3: NEGATIVE_LIEN | F3: 45944.275 | G3: 35 | H3: 0 | I3: 0 | K3: Y | L3: SUCCESS | M3: Balance not available; negative lien marked
A4: ACT-0002-01 | B4: I4C-CASE-2025-0002 | C4: 31608230000002 | D4: INC-0002-01 | E4: HOLD | F4: 45950.08 | G4: 250.66 | H4: 250.66 | I4: 250.66 | J4: LIEN6231665876 | K4: N | L4: SUCCESS | M4: Hold placed successfully
A5: ACT-0002-02 | B5: I4C-CASE-2025-0002 | C5: 31608230000002 | D5: INC-0002-02 | E5: HOLD | F5: 45950.08 | G5: 250.52 | H5: 250.52 | I5: 250.52 | J5: LIEN6690967054 | K5: N | L5: SUCCESS | M5: Hold placed successfully
A6: ACT-0002-03 | B6: I4C-CASE-2025-0002 | C6: 31608230000002 | D6: INC-0002-03 | E6: HOLD | F6: 45950.08 | G6: 99.8 | H6: 99.8 | I6: 99.8 | J6: LIEN6889373467 | K6: N | L6: SUCCESS | M6: Hold placed successfully
A7: ACT-0003-01 | B7: I4C-CASE-2025-0003 | C7: 31608230000003 | D7: INC-0003-01 | E7: HOLD | F7: 45955.947 | G7: 9999.92 | H7: 9999.92 | I7: 9999.92 | J7: LIEN8233749894 | K7: N | L7: SUCCESS | M7: Hold placed successfully
A8: ACT-0003-02 | B8: I4C-CASE-2025-0003 | C8: 31608230000003 | D8: INC-0003-02 | E8: HOLD | F8: 45955.947 | G8: 1250.76 | H8: 1250.76 | I8: 1250.76 | J8: LIEN3435240824 | K8: N | L8: SUCCESS | M8: Hold placed successfully
A9: ACT-0004-01 | B9: I4C-CASE-2025-0004 | C9: 31608230000004 | D9: INC-0004-01 | E9: HOLD | F9: 45936.961 | G9: 500.69 | H9: 324.33 | I9: 324.33 | J9: LIEN2146584044 | K9: N | L9: SUCCESS | M9: Partial hold due to insufficient balance
A10: ACT-0004-02 | B10: I4C-CASE-2025-0004 | C10: 31608230000004 | D10: INC-0004-02 | E10: HOLD | F10: 45936.961 | G10: 250.32 | H10: 175.85 | I10: 175.85 | J10: LIEN9727875588 | K10: N | L10: SUCCESS | M10: Partial hold due to insufficient balance
A11: ACT-0004-03 | B11: I4C-CASE-2025-0004 | C11: 31608230000004 | D11: INC-0004-03 | E11: HOLD | F11: 45936.961 | G11: 4999.48 | H11: 2131.41 | I11: 2131.41 | J11: LIEN5339636057 | K11: N | L11: SUCCESS | M11: Partial hold due to insufficient balance
A12: ACT-0005-01 | B12: I4C-CASE-2025-0005 | C12: 31608230000005 | D12: INC-0005-01 | E12: HOLD | F12: 45957.173 | G12: 500.64 | H12: 0 | I12: 0 | K12: N | L12: FAIL | M12: Account not found
A13: ACT-0005-02 | B13: I4C-CASE-2025-0005 | C13: 31608230000005 | D13: INC-0005-02 | E13: HOLD | F13: 45957.173 | G13: 9999.8 | H13: 0 | I13: 0 | K13: N | L13: FAIL | M13: Account not found
A14: ACT-0006-01 | B14: I4C-CASE-2025-0006 | C14: 31608230000006 | D14: INC-0006-01 | E14: HOLD | F14: 45947.576 | G14: 250.86 | H14: 250.86 | I14: 250.86 | J14: LIEN0847007661 | K14: N | L14: SUCCESS | M14: Hold placed successfully
A15: ACT-0007-01 | B15: I4C-CASE-2025-0007 | C15: 31608230000007 | D15: INC-0007-01 | E15: HOLD | F15: 45951.577 | G15: 4999.74 | H15: 4999.74 | I15: 4999.74 | J15: LIEN8998094024 | K15: N | L15: SUCCESS | M15: Hold placed successfully
A16: ACT-0008-01 | B16: I4C-CASE-2025-0008 | C16: 31608230000008 | D16: INC-0008-01 | E16: HOLD | F16: 45951.974 | G16: 1250.67 | H16: 1250.67 | I16: 1250.67 | J16: LIEN5523124329 | K16: N | L16: SUCCESS | M16: Hold placed successfully
A17: ACT-0008-02 | B17: I4C-CASE-2025-0008 | C17: 31608230000008 | D17: INC-0008-02 | E17: HOLD | F17: 45951.974 | G17: 500.71 | H17: 500.71 | I17: 500.71 | J17: LIEN1277997995 | K17: N | L17: SUCCESS | M17: Hold placed successfully
A18: ACT-0009-01 | B18: I4C-CASE-2025-0009 | C18: 31608230000009 | D18: INC-0009-01 | E18: HOLD | F18: 45960.41 | G18: 4999.14 | H18: 4999.14 | I18: 4999.14 | J18: LIEN1888059296 | K18: N | L18: SUCCESS | M18: Hold placed successfully
A19: ACT-0010-01 | B19: I4C-CASE-2025-0010 | C19: 31608230000010 | D19: INC-0010-01 | E19: NEGATIVE_LIEN | F19: 45948.358 | G19: 9999.71 | H19: 0 | I19: 0 | K19: Y | L19: SUCCESS | M19: Balance not available; negative lien marked
A20: ACT-0011-01 | B20: I4C-CASE-2025-0011 | C20: 31608230000011 | D20: INC-0011-01 | E20: HOLD | F20: 45933.512 | G20: 9999.66 | H20: 9999.66 | I20: 9999.66 | J20: LIEN6275705964 | K20: N | L20: SUCCESS | M20: Hold placed successfully
A21: ACT-0012-01 | B21: I4C-CASE-2025-0012 | C21: 31608230000012 | D21: INC-0012-01 | E21: HOLD | F21: 45946.894 | G21: 99.79 | H21: 76.75 | I21: 76.75 | J21: LIEN9439690784 | K21: N | L21: SUCCESS | M21: Partial hold due to insufficient balance
A22: ACT-0012-02 | B22: I4C-CASE-2025-0012 | C22: 31608230000012 | D22: INC-0012-02 | E22: HOLD | F22: 45946.894 | G22: 99.16 | H22: 58.02 | I22: 58.02 | J22: LIEN4736471027 | K22: N | L22: SUCCESS | M22: Partial hold due to insufficient balance
A23: ACT-0013-01 | B23: I4C-CASE-2025-0013 | C23: 31608230000013 | D23: INC-0013-01 | E23: HOLD | F23: 45955.415 | G23: 35.57 | H23: 0 | I23: 0 | K23: N | L23: PENDING_RETRY | M23: CBS timeout; will retry
A24: ACT-0013-02 | B24: I4C-CASE-2025-0013 | C24: 31608230000013 | D24: INC-0013-02 | E24: HOLD | F24: 45955.415 | G24: 99.33 | H24: 0 | I24: 0 | K24: N | L24: PENDING_RETRY | M24: CBS timeout; will retry
A25: ACT-0013-03 | B25: I4C-CASE-2025-0013 | C25: 31608230000013 | D25: INC-0013-03 | E25: HOLD | F25: 45955.415 | G25: 99.82 | H25: 0 | I25: 0 | K25: N | L25: PENDING_RETRY | M25: CBS timeout; will retry
A26: ACT-0014-01 | B26: I4C-CASE-2025-0014 | C26: 31608230000014 | D26: INC-0014-01 | E26: HOLD | F26: 45947.412 | G26: 9999.09 | H26: 0 | I26: 0 | K26: N | L26: FAIL | M26: Account not found
A27: ACT-0014-02 | B27: I4C-CASE-2025-0014 | C27: 31608230000014 | D27: INC-0014-02 | E27: HOLD | F27: 45947.412 | G27: 9999.3 | H27: 0 | I27: 0 | K27: N | L27: FAIL | M27: Account not found
A28: ACT-0015-01 | B28: I4C-CASE-2025-0015 | C28: 31608230000015 | D28: INC-0015-01 | E28: NEGATIVE_LIEN | F28: 45936.828 | G28: 500.09 | H28: 0 | I28: 0 | K28: Y | L28: SUCCESS | M28: Balance not available; negative lien marked
A29: ACT-0016-01 | B29: I4C-CASE-2025-0016 | C29: 31608230000016 | D29: INC-0016-01 | E29: HOLD | F29: 45952.696 | G29: 250.88 | H29: 179.26 | I29: 179.26 | J29: LIEN2708668826 | K29: N | L29: SUCCESS | M29: Partial hold due to insufficient balance
A30: ACT-0017-01 | B30: I4C-CASE-2025-0017 | C30: 31608230000017 | D30: INC-0017-01 | E30: HOLD | F30: 45949.383 | G30: 99.33 | H30: 99.33 | I30: 99.33 | J30: LIEN6793341016 | K30: N | L30: SUCCESS | M30: Hold placed successfully
A31: ACT-0017-02 | B31: I4C-CASE-2025-0017 | C31: 31608230000017 | D31: INC-0017-02 | E31: HOLD | F31: 45949.383 | G31: 4999.67 | H31: 4999.67 | I31: 4999.67 | J31: LIEN8700217659 | K31: N | L31: SUCCESS | M31: Hold placed successfully
A32: ACT-0018-01 | B32: I4C-CASE-2025-0018 | C32: 31608230000018 | D32: INC-0018-01 | E32: HOLD | F32: 45948.86 | G32: 250.55 | H32: 250.55 | I32: 250.55 | J32: LIEN6519398280 | K32: N | L32: SUCCESS | M32: Hold placed successfully
A33: ACT-0018-02 | B33: I4C-CASE-2025-0018 | C33: 31608230000018 | D33: INC-0018-02 | E33: HOLD | F33: 45948.86 | G33: 99.46 | H33: 99.46 | I33: 99.46 | J33: LIEN7374167243 | K33: N | L33: SUCCESS | M33: Hold placed successfully
A34: ACT-0019-01 | B34: I4C-CASE-2025-0019 | C34: 31608230000019 | D34: INC-0019-01 | E34: NEGATIVE_LIEN | F34: 45938.258 | G34: 250.04 | H34: 0 | I34: 0 | K34: Y | L34: SUCCESS | M34: Balance not available; negative lien marked
A35: ACT-0019-02 | B35: I4C-CASE-2025-0019 | C35: 31608230000019 | D35: INC-0019-02 | E35: NEGATIVE_LIEN | F35: 45938.258 | G35: 99.37 | H35: 0 | I35: 0 | K35: Y | L35: SUCCESS | M35: Balance not available; negative lien marked
A36: ACT-0020-01 | B36: I4C-CASE-2025-0020 | C36: 31608230000020 | D36: INC-0020-01 | E36: HOLD | F36: 45936.928 | G36: 250.35 | H36: 250.35 | I36: 250.35 | J36: LIEN5458929750 | K36: N | L36: SUCCESS | M36: Hold placed successfully
A37: ACT-0020-02 | B37: I4C-CASE-2025-0020 | C37: 31608230000020 | D37: INC-0020-02 | E37: HOLD | F37: 45936.928 | G37: 99.71 | H37: 99.71 | I37: 99.71 | J37: LIEN7012770632 | K37: N | L37: SUCCESS | M37: Hold placed successfully
A38: ACT-0021-01 | B38: I4C-CASE-2025-0021 | C38: 31608230000021 | D38: INC-0021-01 | E38: NEGATIVE_LIEN | F38: 45937.799 | G38: 35.53 | H38: 0 | I38: 0 | K38: Y | L38: SUCCESS | M38: Balance not available; negative lien marked
A39: ACT-0021-02 | B39: I4C-CASE-2025-0021 | C39: 31608230000021 | D39: INC-0021-02 | E39: NEGATIVE_LIEN | F39: 45937.799 | G39: 99.75 | H39: 0 | I39: 0 | K39: Y | L39: SUCCESS | M39: Balance not available; negative lien marked
A40: ACT-0022-01 | B40: I4C-CASE-2025-0022 | C40: 31608230000022 | D40: INC-0022-01 | E40: HOLD | F40: 45937.117 | G40: 500.86 | H40: 0 | I40: 0 | K40: N | L40: PENDING_RETRY | M40: CBS timeout; will retry
...

Sheet Bank_StatusUpdate_Request
A1: request_id | B1: acknowledgement_no | C1: job_id | D1: sent_at | E1: content_type | F1: authorization_type | G1: payload_encrypted | H1: transaction_count
A2: REQ-00001 | B2: 31608230000001 | C2: a809e351-37a8-4017-9977-dc4d0e60ec7b | D2: 45944.279 | E2: text/plain | F2: Bearer <JWT_TOKEN> | G2: Y | H2: 2
A3: REQ-00002 | B3: 31608230000002 | C3: dc8ac3a9-c97b-4688-a12b-989696a01ca5 | D3: 45950.081 | E3: text/plain | F3: Bearer <JWT_TOKEN> | G3: Y | H3: 3
A4: REQ-00003 | B4: 31608230000003 | C4: a7cd9031-8026-4865-a5bf-503cb85d456b | D4: 45955.947 | E4: text/plain | F4: Bearer <JWT_TOKEN> | G4: Y | H4: 2
A5: REQ-00004 | B5: 31608230000004 | C5: 260f5953-5ef8-4b0a-9ad0-aa82d14417c5 | D5: 45936.966 | E5: text/plain | F5: Bearer <JWT_TOKEN> | G5: Y | H5: 3
A6: REQ-00005 | B6: 31608230000005 | C6: b84e9000-babf-4700-b34e-ccc2ca1554ce | D6: 45957.174 | E6: text/plain | F6: Bearer <JWT_TOKEN> | G6: Y | H6: 2
A7: REQ-00006 | B7: 31608230000006 | C7: 87ad8bc0-8306-4d41-95e4-f3591d26c43f | D7: 45947.582 | E7: text/plain | F7: Bearer <JWT_TOKEN> | G7: Y | H7: 1
A8: REQ-00007 | B8: 31608230000007 | C8: 0797d398-04e1-458f-a273-42c1b0a09584 | D8: 45951.581 | E8: text/plain | F8: Bearer <JWT_TOKEN> | G8: Y | H8: 1
A9: REQ-00008 | B9: 31608230000008 | C9: 382fbbbe-527b-4d04-ae9f-ca5e0427223c | D9: 45951.978 | E9: text/plain | F9: Bearer <JWT_TOKEN> | G9: Y | H9: 2
A10: REQ-00009 | B10: 31608230000009 | C10: 8ebca7ef-f7dc-40cd-a99e-7537d57a4b40 | D10: 45960.412 | E10: text/plain | F10: Bearer <JWT_TOKEN> | G10: Y | H10: 1
A11: REQ-00010 | B11: 31608230000010 | C11: 7ccbb3c8-ddb8-415f-9d43-4be9e9a11433 | D11: 45948.365 | E11: text/plain | F11: Bearer <JWT_TOKEN> | G11: Y | H11: 1
A12: REQ-00011 | B12: 31608230000011 | C12: f2a9ed34-112d-43e1-99ae-06af4acc27ef | D12: 45933.513 | E12: text/plain | F12: Bearer <JWT_TOKEN> | G12: Y | H12: 1
A13: REQ-00012 | B13: 31608230000012 | C13: fb1b1cf6-96ac-46a4-84ac-3eacc39b2bd8 | D13: 45946.899 | E13: text/plain | F13: Bearer <JWT_TOKEN> | G13: Y | H13: 2
... A31: REQ-00030 | B31: 31608230000030 | C31: 38c47fb7-350b-4e16-bd31-1c77d36f369d | D31: 45935.006 | E31: text/plain | F31: Bearer <JWT_TOKEN> | G31: Y | H31: 1

Sheet Bank_StatusUpdate_TxnDetails
A1: request_id | B1: acknowledgement_no | C1: job_id | D1: incident_id | E1: root_rrn_transaction_id | F1: root_bankid | G1: root_account_number | H1: amount | I1: transaction_datetime | J1: disputed_amount | K1: status_code | L1: remarks | M1: phone_number | N1: pan_number | O1: email | P1: root_ifsc_code | Q1: root_effective_balance | R1: negative_lien_flag | S1: hold_reference | T1: held_amount
A2: REQ-00001 | B2: 31608230000001 | C2: a809e351-37a8-4017-9977-dc4d0e60ec7b | D2: INC-0001-01 | E2: 2475107991183 | F2: 8 | G2: 49808412411824 | H2: 1250.27 | I2: 2025-10-14 02:35:00 | J2: 1250.27 | K2: 20010 | L2: Balance not available; negative lien marked | M2: 9869232260 | N2: FXKZN3421M | O2: cust0733@mail.com | P2: YESB0354278 | Q2: 3991.23 | R2: Y | T2: 0
A3: REQ-00001 | B3: 31608230000001 | C3: a809e351-37a8-4017-9977-dc4d0e60ec7b | D3: INC-0001-02 | E3: 4935348740164 | F3: 12 | G3: 11280598262045 | H3: 35 | I3: 2025-10-14 03:37:00 | J3: 35 | K3: 20010 | L3: Balance not available; negative lien marked | M3: 0000000000 | N3: layer 0 | O3: layer 0 | P3: layer 0 | Q3: 0 | R3: Y | T3: 0
A4: REQ-00002 | B4: 31608230000002 | C4: dc8ac3a9-c97b-4688-a12b-989696a01ca5 | D4: INC-0002-01 | E4: 3406088356159 | F4: 12 | G4: 82366299468044 | H4: 250.66 | I4: 2025-10-19 22:36:00 | J4: 250.66 | K4: 20000 | L4: Hold placed successfully | M4: 0000000000 | N4: layer 0 | O4: layer 0 | P4: layer 0 | Q4: 0 | R4: N | S4: LIEN6231665876 | T4: 250.66
A5: REQ-00002 | B5: 31608230000002 | C5: dc8ac3a9-c97b-4688-a12b-989696a01ca5 | D5: INC-0002-02 | E5: 3699577738721 | F5: 13 | G5: 00379176936763 | H5: 250.52 | I5: 2025-10-19 23:02:00 | J5: 250.52 | K5: 20000 | L5: Hold placed successfully | M5: 9656272980 | N5: MSSVA1627F | O5: cust0465@mail.com | P5: UBIN0134332 | Q5: 664.13 | R5: N | S5: LIEN6690967054 | T5: 250.52
A6: REQ-00002 | B6: 31608230000002 | C6: dc8ac3a9-c97b-4688-a12b-989696a01ca5 | D6: INC-0002-03 | E6: 2016328708317 | F6: 13 | G6: 27743487347143 | H6: 99.8 | I6: 2025-10-19 23:25:00 | J6: 99.8 | K6: 20000 | L6: Hold placed successfully | M6: 9556464170 | N6: XRBLH1003G | O6: cust0923@mail.com | P6: UBIN0798687 | Q6: 194.22 | R6: N | S6: LIEN6889373467 | T6: 99.8
A7: REQ-00003 | B7: 31608230000003 | C7: a7cd9031-8026-4865-a5bf-503cb85d456b | D7: INC-0003-01 | E7: 0671657262849 | F7: 14 | G7: 73799650752735 | H7: 9999.92 | I7: 2025-10-25 20:21:00 | J7: 9999.92 | K7: 20000 | L7: Hold placed successfully | M7: 9084271094 | N7: PPOKF0471C | O7: cust6719@mail.com | P7: UCBA0945314 | Q7: 2961.95 | R7: N | S7: LIEN8233749894 | T7: 9999.92
A8: REQ-00003 | B8: 31608230000003 | C8: a7cd9031-8026-4865-a5bf-503cb85d456b | D8: INC-0003-02 | E8: 4549480831367 | F8: 36 | G8: 34957885685574 | H8: 1250.76 | I8: 2025-10-25 20:19:00 | J8: 1250.76 | K8: 20000 | L8: Hold placed successfully | M8: 9022941318 | N8: YNTTZ9386O | O8: cust7496@mail.com | P8: VARA0701436 | Q8: 1179.59 | R8: N | S8: LIEN3435240824 | T8: 1250.76
A9: REQ-00004 | B9: 31608230000004 | C9: 260f5953-5ef8-4b0a-9ad0-aa82d14417c5 | D9: INC-0004-01 | E9: 3242102499471 | F9: 12 | G9: 06594013990490 | H9: 500.69 | I9: 2025-10-06 20:52:00 | J9: 500.69 | K9: 20005 | L9: Partial hold due to insufficient balance | M9: 9627028951 | N9: ODQOA2621P | O9: cust4596@mail.com | P9: CNRB0887719 | Q9: 3074.1 | R9: N | S9: LIEN2146584044 | T9: 324.33
A10: REQ-00004 | B10: 31608230000004 | C10: 260f5953-5ef8-4b0a-9ad0-aa82d14417c5 | D10: INC-0004-02 | E10: 2787429671756 | F10: 9 | G10: 07154516808760 | H10: 250.32 | I10: 2025-10-06 18:56:00 | J10: 250.32 | K10: 20005 | L10: Partial hold due to insufficient balance | M10: 0000000000 | N10: layer 0 | O10: layer 0 | P10: layer 0 | Q10: 0 | R10: N | S10: LIEN9727875588 | T10: 175.85
A11: REQ-00004 | B11: 31608230000004 | C11: 260f5953-5ef8-4b0a-9ad0-aa82d14417c5 | D11: INC-0004-03 | E11: 3859770348247 | F11: 11 | G11: 13171274846773 | H11: 4999.48 | I11: 2025-10-06 19:54:00 | J11: 4999.48 | K11: 20005 | L11: Partial hold due to insufficient balance | M11: 0000000000 | N11: layer 0 | O11: layer 0 | P11: layer 0 | Q11: 0 | R11: N | S11: LIEN5339636057 | T11: 2131.41
A12: REQ-00005 | B12: 31608230000005 | C12: b84e9000-babf-4700-b34e-ccc2ca1554ce | D12: INC-0005-01 | E12: 9222196937923 | F12: 7 | G12: 59464743671369 | H12: 500.64 | I12: 2025-10-27 02:40:00 | J12: 500.64 | K12: 40001 | L12: Account not found; effective balance was -362.36 (sent as 0 per rule) | M12: 9712368516 | N12: AIRDO5496U | O12: cust5137@mail.com | P12: KKBK0748217 | Q12: 0 | R12: N | T12: 0
A13: REQ-00005 | B13: 31608230000005 | C13: b84e9000-babf-4700-b34e-ccc2ca1554ce | D13: INC-0005-02 | E13: 5944064090974 | F13: 11 | G13: 70952145623285 | H13: 9999.8 | I13: 2025-10-27 02:49:00 | J13: 9999.8 | K13: 40001 | L13: Account not found | M13: 9859317461 | N13: EBBJP1138E | O13: cust6758@mail.com | P13: IDFB0942104 | Q13: 1805.2 | R13: N | T13: 0
A14: REQ-00006 | B14: 31608230000006 | C14: 87ad8bc0-8306-4d41-95e4-f3591d26c43f | D14: INC-0006-01 | E14: 2931839335290 | F14: 12 | G14: 39502402681177 | H14: 250.86 | I14: 2025-10-17 12:52:00 | J14: 250.86 | K14: 20000 | L14: Hold placed successfully | M14: 0000000000 | N14: layer 0 | O14: layer 0 | P14: layer 0 | Q14: 0 | R14: N | S14: LIEN0847007661 | T14: 250.86
A15: REQ-00007 | B15: 31608230000007 | C15: 0797d398-04e1-458f-a273-42c1b0a09584 | D15: INC-0007-01 | E15: 5654527111161 | F15: 7 | G15: 56049451983273 | H15: 4999.74 | I15: 2025-10-21 11:08:00 | J15: 4999.74 | K15: 20000 | L15: Hold placed successfully | M15: 0000000000 | N15: layer 0 | O15: layer 0 | P15: layer 0 | Q15: 0 | R15: N | S15: LIEN8998094024 | T15: 4999.74
A16: REQ-00008 | B16: 31608230000008 | C16: 382fbbbe-527b-4d04-ae9f-ca5e0427223c | D16: INC-0008-01 | E16: 9764381561497 | F16: 14 | G16: 24451076226838 | H16: 1250.67 | I16: 2025-10-21 21:59:00 | J16: 1250.67 | K16: 20000 | L16: Hold placed successfully | M16: 0000000000 | N16: layer 0 | O16: layer 0 | P16: layer 0 | Q16: 0 | R16: N | S16: LIEN5523124329 | T16: 1250.67
A17: REQ-00008 | B17: 31608230000008 | C17: 382fbbbe-527b-4d04-ae9f-ca5e0427223c | D17: INC-0008-02 | E17: 8516060715969 | F17: 8 | G17: 51613696816453 | H17: 500.71 | I17: 2025-10-21 21:41:00 | J17: 500.71 | K17: 20000 | L17: Hold placed successfully | M17: 9271774490 | N17: LQCJO7005J | O17: cust1199@mail.com | P17: YESB0605297 | Q17: 2288.87 | R17: N | S17: LIEN1277997995 | T17: 500.71
A18: REQ-00009 | B18: 31608230000009 | C18: 8ebca7ef-f7dc-40cd-a99e-7537d57a4b40 | D18: INC-0009-01 | E18: 5151864492519 | F18: 14 | G18: 52816850542357 | H18: 4999.14 | I18: 2025-10-30 08:11:00 | J18: 4999.14 | K18: 20000 | L18: Hold placed successfully | M18: 9229270653 | N18: OTJYX7383J | O18: cust7359@mail.com | P18: UCBA0291486 | Q18: 4914.42 | R18: N | S18: LIEN1888059296 | T18: 4999.14
A19: REQ-00010 | B19: 31608230000010 | C19: 7ccbb3c8-ddb8-415f-9d43-4be9e9a11433 | D19: INC-0010-01 | E19: 6068536153051 | F19: 9 | G19: 79010432898614 | H19: 9999.71 | I19: 2025-10-18 04:48:00 | J19: 9999.71 | K19: 20010 | L19: Balance not available; negative lien marked | M19: 9711798089 | N19: HWEJN0953S | O19: cust6218@mail.com | P19: INDB0204727 | Q19: 4860.6 | R19: Y | T19: 0
A20: REQ-00011 | B20: 31608230000011 | C20: f2a9ed34-112d-43e1-99ae-06af4acc27ef | D20: INC-0011-01 | E20: 0548687403450 | F20: 13 | G20: 77584161692845 | H20: 9999.66 | I20: 2025-10-03 11:24:00 | J20: 9999.66 | K20: 20000 | L20: Hold placed successfully | M20: 9165820297 | N20: BECHY5569B | O20: cust9275@mail.com | P20: UBIN0667652 | Q20: 1546.07 | R20: N | S20: LIEN6275705964 | T20: 9999.66
A21: REQ-00012 | B21: 31608230000012 | C21: fb1b1cf6-96ac-46a4-84ac-3eacc39b2bd8 | D21: INC-0012-01 | E21: 1884422583132 | F21: 13 | G21: 46786691251778 | H21: 99.79 | I21: 2025-10-16 19:43:00 | J21: 99.79 | K21: 20005 | L21: Partial hold due to insufficient balance | M21: 0000000000 | N21: layer 0 | O21: layer 0 | P21: layer 0 | Q21: 0 | R21: N | S21: LIEN9439690784 | T21: 76.75
A22: REQ-00012 | B22: 31608230000012 | C22: fb1b1cf6-96ac-46a4-84ac-3eacc39b2bd8 | D22: INC-0012-02 | E22: 5289226801824 | F22: 13 | G22: 42498182992299 | H22: 99.16 | I22: 2025-10-16 20:18:00 | J22: 99.16 | K22: 20005 | L22: Partial hold due to insufficient balance | M22: 9773592555 | N22: MEYLQ8153O | O22: cust1473@mail.com | P22: UBIN0841438 | Q22: 274.83 | R22: N | S22: LIEN4736471027 | T22: 58.02
A23: REQ-00013 | B23: 31608230000013 | C23: 17c42136-f082-48bc-b610-0672d0d42072 | D23: INC-0013-01 | E23: 7480162456506 | F23: 12 | G23: 99121655852398 | H23: 35.57 | I23: 2025-10-25 07:58:00 | J23: 35.57 | K23: 50001 | L23: CBS timeout; will retry | M23: 0000000000 | N23: layer 0 | O23: layer 0 | P23: layer 0 | Q23: 0 | R23: N | T23: 0
A24: REQ-00013 | B24: 31608230000013 | C24: 17c42136-f082-48bc-b610-0672d0d42072 | D24: INC-0013-02 | E24: 6800025787298 | F24: 9 | G24: 88794705516940 | H24: 99.33 | I24: 2025-10-25 08:09:00 | J24: 99.33 | K24: 50001 | L24: CBS timeout; will retry | M24: 9549733484 | N24: HJYJW3757L | O24: cust8441@mail.com | P24: INDB0694958 | Q24: 2654.12 | R24: N | T24: 0
A25: REQ-00013 | B25: 31608230000013 | C25: 17c42136-f082-48bc-b610-0672d0d42072 | D25: INC-0013-03 | E25: 9749930972896 | F25: 8 | G25: 63689702838578 | H25: 99.82 | I25: 2025-10-25 09:22:00 | J25: 99.82 | K25: 50001 | L25: CBS timeout; will retry | M25: 0000000000 | N25: layer 0 | O25: layer 0 | P25: layer 0 | Q25: 0 | R25: N | T25: 0
A26: REQ-00014 | B26: 31608230000014 | C26: 85909e1c-12aa-470f-981c-2741dccddf7f | D26: INC-0014-01 | E26: 1208267734540 | F26: 7 | G26: 24004991547887 | H26: 9999.09 | I26: 2025-10-17 07:24:00 | J26: 9999.09 | K26: 40001 | L26: Account not found | M26: 0000000000 | N26: layer 0 | O26: layer 0 | P26: layer 0 | Q26: 0 | R26: N | T26: 0
A27: REQ-00014 | B27: 31608230000014 | C27: 85909e1c-12aa-470f-981c-2741dccddf7f | D27: INC-0014-02 | E27: 2874315274205 | F27: 14 | G27: 22753046374549 | H27: 9999.3 | I27: 2025-10-17 08:56:00 | J27: 9999.3 | K27: 40001 | L27: Account not found | M27: 0000000000 | N27: layer 0 | O27: layer 0 | P27: layer 0 | Q27: 0 | R27: N | T27: 0
A28: REQ-00015 | B28: 31608230000015 | C28: e1bf6439-b35d-4699-8f1a-9e23440e90aa | D28: INC-0015-01 | E28: 8839822587139 | F28: 7 | G28: 08740640391065 | H28: 500.09 | I28: 2025-10-06 17:41:00 | J28: 500.09 | K28: 20010 | L28: Balance not available; negative lien marked | M28: 9622656766 | N28: CVVRE5128M | O28: cust8230@mail.com | P28: KKBK0728679 | Q28: 3658.99 | R28: Y | T28: 0
A29: REQ-00016 | B29: 31608230000016 | C29: 79a28af4-62f8-4124-bbf2-32c6e9d92329 | D29: INC-0016-01 | E29: 8302843959953 | F29: 11 | G29: 26870568566246 | H29: 250.88 | I29: 2025-10-22 14:07:00 | J29: 250.88 | K29: 20005 | L29: Partial hold due to insufficient balance | M29: 9435175183 | N29: BIMVT9013Z | O29: cust9837@mail.com | P29: IDFB0644089 | Q29: 648.89 | R29: N | S29: LIEN2708668826 | T29: 179.26
A30: REQ-00017 | B30: 31608230000017 | C30: 8f9d0193-d0ef-4ff0-8143-60e737c9760e | D30: INC-0017-01 | E30: 6093204899642 | F30: 11 | G30: 72522872808010 | H30: 99.33 | I30: 2025-10-19 06:20:00 | J30: 99.33 | K30: 20000 | L30: Hold placed successfully | M30: 9803397401 | N30: VIRSV0250G | O30: cust9261@mail.com | P30: IDFB0785477 | Q30: 1146.02 | R30: N | S30: LIEN6793341016 | T30: 99.33
A31: REQ-00017 | B31: 31608230000017 | C31: 8f9d0193-d0ef-4ff0-8143-60e737c9760e | D31: INC-0017-02 | E31: 0623120387509 | F31: 36 | G31: 00848408621182 | H31: 4999.67 | I31: 2025-10-19 04:52:00 | J31: 4999.67 | K31: 20000 | L31: Hold placed successfully; effective balance was -337.06 (sent as 0 per rule) | M31: 9939685621 | N31: QXLBD6315T | O31: cust9965@mail.com | P31: VARA0700886 | Q31: 0 | R31: N | S31: LIEN8700217659 | T31: 4999.67
A32: REQ-00018 | B32: 31608230000018 | C32: a392623d-7711-4020-a2c9-793555384b0b | D32: INC-0018-01 | E32: 1212678886101 | F32: 13 | G32: 83982622444721 | H32: 250.55 | I32: 2025-10-18 17:42:00 | J32: 250.55 | K32: 20000 | L32: Hold placed successfully | M32: 9266179796 | N32: RQWNR0589U | O32: cust1135@mail.com | P32: UBIN0604661 | Q32: 414.86 | R32: N | S32: LIEN6519398280 | T32: 250.55
A33: REQ-00018 | B33: 31608230000018 | C33: a392623d-7711-4020-a2c9-793555384b0b | D33: INC-0018-02 | E33: 2646471543799 | F33: 7 | G33: 56924593752654 | H33: 99.46 | I33: 2025-10-18 18:58:00 | J33: 99.46 | K33: 20000 | L33: Hold placed successfully | M33: 0000000000 | N33: layer 0 | O33: layer 0 | P33: layer 0 | Q33: 0 | R33: N | S33: LIEN7374167243 | T33: 99.46
A34: REQ-00019 | B34: 31608230000019 | C34: 5c2cbf12-f130-47b1-a973-31250ad54c30 | D34: INC-0019-01 | E34: 4573875717751 | F34: 7 | G34: 82586736226609 | H34: 250.04 | I34: 2025-10-08 05:26:00 | J34: 250.04 | K34: 20010 | L34: Balance not available; negative lien marked | M34: 9286692966 | N34: FPURW2827J | O34: cust2257@mail.com | P34: KKBK0512382 | Q34: 2906.75 | R34: Y | T34: 0
A35: REQ-00019 | B35: 31608230000019 | C35: 5c2cbf12-f130-47b1-a973-31250ad54c30 | D35: INC-0019-02 | E35: 3796603341918 | F35: 8 | G35: 96915579249912 | H35: 99.37 | I35: 2025-10-08 03:58:00 | J35: 99.37 | K35: 20010 | L35: Balance not available; negative lien marked | M35: 0000000000 | N35: layer 0 | O35: layer 0 | P35: layer 0 | Q35: 0 | R35: Y | T35: 0
A36: REQ-00020 | B36: 31608230000020 | C36: 847dbb0e-b66b-41c0-b403-75ca9ecdc286 | D36: INC-0020-01 | E36: 8580783613407 | F36: 8 | G36: 29233095849825 | H36: 250.35 | I36: 2025-10-06 20:03:00 | J36: 250.35 | K36: 20000 | L36: Hold placed successfully | M36: 0000000000 | N36: layer 0 | O36: layer 0 | P36: layer 0 | Q36: 0 | R36: N | S36: LIEN5458929750 | T36: 250.35
A37: REQ-00020 | B37: 31608230000020 | C37: 847dbb0e-b66b-41c0-b403-75ca9ecdc286 | D37: INC-0020-02 | E37: 4494812604223 | F37: 14 | G37: 71168457759017 | H37: 99.71 | I37: 2025-10-06 18:41:00 | J37: 99.71 | K37: 20000 | L37: Hold placed successfully | M37: 0000000000 | N37: layer 0 | O37: layer 0 | P37: layer 0 | Q37: 0 | R37: N | S37: LIEN7012770632 | T37: 99.71
A38: REQ-00021 | B38: 31608230000021 | C38: cc2c80ef-e1cd-4a3f-a6fe-9aad3850ab1b | D38: INC-0021-01 | E38: 1361115542622 | F38: 9 | G38: 73112196565234 | H38: 35.53 | I38: 2025-10-07 16:14:00 | J38: 35.53 | K38: 20010 | L38: Balance not available; negative lien marked | M38: 0000000000 | N38: layer 0 | O38: layer 0 | P38: layer 0 | Q38: 0 | R38: Y | T38: 0
A39: REQ-00021 | B39: 31608230000021 | C39: cc2c80ef-e1cd-4a3f-a6fe-9aad3850ab1b | D39: INC-0021-02 | E39: 1389994043898 | F39: 7 | G39: 91805526965827 | H39: 99.75 | I39: 2025-10-07 16:05:00 | J39: 99.75 | K39: 20010 | L39: Balance not available; negative lien marked | M39: 9068486661 | N39: URRTE4141Q | O39: cust3285@mail.com | P39: KKBK0376137 | Q39: 1649.02 | R39: Y | T39: 0
A40: REQ-00022 | B40: 31608230000022 | C40: c448c5ea-5f48-4c6a-bd8f-92d098983753 | D40: INC-0022-01 | E40: 5648149177850 | F40: 9 | G40: 00030756220863 | H40: 500.86 | I40: 2025-10-07 00:51:00 | J40: 500.86 | K40: 50001 | L40: CBS timeout; will retry | M40: 0000000000 | N40: layer 0 | O40: layer 0 | P40: layer 0 | Q40: 0 | R40: N | T40: 0
...

Sheet I4C_StatusUpdate_Response
A1: request_id | B1: i4c_response_code | C1: i4c_message | D1: received_at | E1: error_flag
A2: REQ-00001 | B2: 00 | C2: Success | D2: 45944.279 | E2: N
A3: REQ-00002 | B3: 00 | C3: Success | D3: 45950.081 | E3: N
A4: REQ-00003 | B4: 00 | C4: Success | D4: 45955.947 | E4: N
A5: REQ-00004 | B5: 00 | C5: Success | D5: 45936.966 | E5: N
A6: REQ-00005 | B6: 00 | C6: Success | D6: 45957.174 | E6: N
A7: REQ-00006 | B7: 00 | C7: Success | D7: 45947.582 | E7: N
A8: REQ-00007 | B8: 00 | C8: Success | D8: 45951.581 | E8: N
A9: REQ-00008 | B9: 00 | C9: Success | D9: 45951.978 | E9: N
A10: REQ-00009 | B10: 00 | C10: Success | D10: 45960.412 | E10: N
A11: REQ-00010 | B11: 00 | C11: Success | D11: 45948.365 | E11: N
A12: REQ-00011 | B12: 00 | C12: Success | D12: 45933.513 | E12: N
A13: REQ-00012 | B13: 00 | C13: Success | D13: 45946.899 | E13: N
... A31: REQ-00030 | B31: 00 | C31: Success | D31: 45935.006 | E31: N

Sheet Workflow_Timeline
A1: case_id | B1: acknowledgement_no | C1: job_id | D1: step_no | E1: step_name | F1: actor | G1: start_time | H1: end_time | I1: step_status | J1: sla_target_minutes | K1: actual_minutes | L1: sla_breached
A2: I4C-CASE-2025-0001 | B2: 31608230000001 | C2: a809e351-37a8-4017-9977-dc4d0e60ec7b | D2: 1 | E2: I4C_PUSH_RECEIVED | F2: I4C | G2: 45944.267 | H2: 45944.267 | I2: COMPLETED | J2: 1 | K2: =(H2-G2)*1440 | L2: =IF(K2>J2,"YES","NO")
A3: I4C-CASE-2025-0001 | B3: 31608230000001 | C3: a809e351-37a8-4017-9977-dc4d0e60ec7b | D3: 2 | E3: BANK_ACK_SENT | F3: Bank-System | G3: 45944.267 | H3: 45944.267 | I3: COMPLETED | J3: 1 | K3: =(H3-G3)*1440 | L3: =IF(K3>J3,"YES","NO")
A4: I4C-CASE-2025-0001 | B4: 31608230000001 | C4: a809e351-37a8-4017-9977-dc4d0e60ec7b | D4: 3 | E4: ENRICHMENT_ROUTING | F4: Bank-System | G4: 45944.267 | H4: 45944.271 | I4: COMPLETED | J4: 15 | K4: =(H4-G4)*1440 | L4: =IF(K4>J4,"YES","NO")
A5: I4C-CASE-2025-0001 | B5: 31608230000001 | C5: a809e351-37a8-4017-9977-dc4d0e60ec7b | D5: 4 | E5: HOLD_ACTION_ATTEMPTED | F5: Bank-Ops | G5: 45944.271 | H5: 45944.275 | I5: COMPLETED | J5: 30 | K5: =(H5-G5)*1440 | L5: =IF(K5>J5,"YES","NO")
A6: I4C-CASE-2025-0001 | B6: 31608230000001 | C6: a809e351-37a8-4017-9977-dc4d0e60ec7b | D6: 5 | E6: STATUS_UPDATE_SENT | F6: Bank-System | G6: 45944.275 | H6: 45944.279 | I6: COMPLETED | J6: 60 | K6: =(H6-G6)*1440 | L6: =IF(K6>J6,"YES","NO")
A7: I4C-CASE-2025-0001 | B7: 31608230000001 | C7: a809e351-37a8-4017-9977-dc4d0e60ec7b | D7: 6 | E7: I4C_STATUS_UPDATE_RESPONSE | F7: I4C | G7: 45944.279 | H7: 45944.279 | I7: COMPLETED | J7: 10 | K7: =(H7-G7)*1440 | L7: =IF(K7>J7,"YES","NO")
A8: I4C-CASE-2025-0002 | B8: 31608230000002 | C8: dc8ac3a9-c97b-4688-a12b-989696a01ca5 | D8: 1 | E8: I4C_PUSH_RECEIVED | F8: I4C | G8: 45950.073 | H8: 45950.073 | I8: COMPLETED | J8: 1 | K8: =(H8-G8)*1440 | L8: =IF(K8>J8,"YES","NO")
A9: I4C-CASE-2025-0002 | B9: 31608230000002 | C9: dc8ac3a9-c97b-4688-a12b-989696a01ca5 | D9: 2 | E9: BANK_ACK_SENT | F9: Bank-System | G9: 45950.073 | H9: 45950.073 | I9: COMPLETED | J9: 1 | K9: =(H9-G9)*1440 | L9: =IF(K9>J9,"YES","NO")
A10: I4C-CASE-2025-0002 | B10: 31608230000002 | C10: dc8ac3a9-c97b-4688-a12b-989696a01ca5 | D10: 3 | E10: ENRICHMENT_ROUTING | F10: Bank-System | G10: 45950.073 | H10: 45950.075 | I10: COMPLETED | J10: 15 | K10: =(H10-G10)*1440 | L10: =IF(K10>J10,"YES","NO")
A11: I4C-CASE-2025-0002 | B11: 31608230000002 | C11: dc8ac3a9-c97b-4688-a12b-989696a01ca5 | D11: 4 | E11: HOLD_ACTION_ATTEMPTED | F11: Bank-Ops | G11: 45950.075 | H11: 45950.08 | I11: COMPLETED | J11: 30 | K11: =(H11-G11)*1440 | L11: =IF(K11>J11,"YES","NO")
A12: I4C-CASE-2025-0002 | B12: 31608230000002 | C12: dc8ac3a9-c97b-4688-a12b-989696a01ca5 | D12: 5 | E12: STATUS_UPDATE_SENT | F12: Bank-System | G12: 45950.08 | H12: 45950.081 | I12: COMPLETED | J12: 60 | K12: =(H12-G12)*1440 | L12: =IF(K12>J12,"YES","NO")
A13: I4C-CASE-2025-0002 | B13: 31608230000002 | C13: dc8ac3a9-c97b-4688-a12b-989696a01ca5 | D13: 6 | E13: I4C_STATUS_UPDATE_RESPONSE | F13: I4C | G13: 45950.081 | H13: 45950.081 | I13: COMPLETED | J13: 10 | K13: =(H13-G13)*1440 | L13: =IF(K13>J13,"YES","NO")
... A181: I4C-CASE-2025-0030 | B181: 31608230000030 | C181: 38c47fb7-350b-4e16-bd31-1c77d36f369d | D181: 6 | E181: I4C_STATUS_UPDATE_RESPONSE | F181: I4C | G181: 45935.006 | H181: 45935.006 | I181: COMPLETED | J181: 10 | K181: =(H181-G181)*1440 | L181: =IF(K181>J181,"YES","NO")

Sheet Meta_BankMaster
A1: bank_name | B1: bank_code | C1: ifsc_prefix | D1: notes
A2: State Bank of India | B2: 1 | D2: Payer bank examples
A3: HDFC Bank | B3: 2 | D3: Payer bank examples
A4: ICICI Bank | B4: 3 | D4: Payer bank examples
A5: Axis Bank | B5: 4 | D5: Payer bank examples
A6: Punjab National Bank | B6: 5 | D6: Payer bank examples
A7: Bank of Baroda | B7: 6 | D7: Payer bank examples
A8: Central Bank of India | B8: 10 | D8: Payer bank examples
A9: Kotak Mahindra Bank | B9: 7 | C9: KKBK | D9: Payee bank / IFSC mapping
A10: Yes Bank | B10: 8 | C10: YESB | D10: Payee bank / IFSC mapping
A11: IndusInd Bank | B11: 9 | C11: INDB | D11: Payee bank / IFSC mapping
A12: IDFC FIRST Bank | B12: 11 | C12: IDFB | D12: Payee bank / IFSC mapping
A13: Canara Bank | B13: 12 | C13: CNRB | D13: Payee bank / IFSC mapping
A14: Union Bank of India | B14: 13 | C14: UBIN | D14: Payee bank / IFSC mapping
A15: UCO Bank | B15: 14 | C15: UCBA | D15: Payee bank / IFSC mapping
A16: Varachha Co-operative Bank | B16: 36 | C16: VARA | D16: Payee bank / IFSC mapping

Sheet Meta_StatusCodes
A1: status_code | B1: status_label | C1: meaning | D1: owner | E1: demo_example_usage
A2: 10000 | B2: RECEIVED | C2: Inbound fraud report received and accepted for processing | D2: System | E2: Use this code in Bank_StatusUpdate_TxnDetails.status_code
A3: 20000 | B3: HOLD_PLACED | C3: Lien/hold placed successfully | D3: Bank Ops | E3: Use this code in Bank_StatusUpdate_TxnDetails.status_code
A4: 20005 | B4: PARTIAL_HOLD | C4: Partial amount held due to insufficient balance | D4: Bank Ops | E4: Use this code in Bank_StatusUpdate_TxnDetails.status_code
A5: 20010 | B5: NEGATIVE_LIEN | C5: Negative lien marked (balance not available) | D5: Bank Ops | E5: Use this code in Bank_StatusUpdate_TxnDetails.status_code
A6: 30000 | B6: HOLD_RELEASED | C6: Hold released after verification/legal direction | D6: Bank HO | E6: Use this code in Bank_StatusUpdate_TxnDetails.status_code
A7: 40001 | B7: ACCOUNT_NOT_FOUND | C7: Beneficiary account not found / invalid details | D7: Bank Ops | E7: Use this code in Bank_StatusUpdate_TxnDetails.status_code
A8: 50001 | B8: DEPENDENCY_TIMEOUT | C8: Upstream dependency timeout (CBS/rail) | D8: System | E8: Use this code in Bank_StatusUpdate_TxnDetails.status_code
A9: 50002 | B9: ENCRYPTION_ERROR | C9: Encryption/Decryption failure | D9: System | E9: Use this code in Bank_StatusUpdate_TxnDetails.status_code

Sheet Bank_Branches
A1: branch_id | B1: branch_name | C1: state | D1: district | E1: ifsc_prefix | F1: region
A2: BR-001 | B2: Demo Branch 001 | C2: TELANGANA | D2: Hyderabad | E2: KKBK | F2: WEST
A3: BR-002 | B3: Demo Branch 002 | C3: WEST BENGAL | D3: Kolkata | E3: UBIN | F3: SOUTH
A4: BR-003 | B4: Demo Branch 003 | C4: GUJARAT | D4: Surat | E4: IDFB | F4: SOUTH
A5: BR-004 | B5: Demo Branch 004 | C5: MAHARASHTRA | D5: Pune | E5: YESB | F5: EAST
A6: BR-005 | B6: Demo Branch 005 | C6: MAHARASHTRA | D6: Pune | E6: UBIN | F6: SOUTH
A7: BR-006 | B7: Demo Branch 006 | C7: TELANGANA | D7: Hyderabad | E7: KKBK | F7: EAST
A8: BR-007 | B8: Demo Branch 007 | C8: MAHARASHTRA | D8: Pune | E8: UCBA | F8: NORTH
A9: BR-008 | B9: Demo Branch 008 | C9: TELANGANA | D9: Hyderabad | E9: UBIN | F9: CENTRAL
A10: BR-009 | B10: Demo Branch 009 | C10: KARNATAKA | D10: Bengaluru Urban | E10: YESB | F10: NORTH
A11: BR-010 | B11: Demo Branch 010 | C11: KARNATAKA | D11: Bengaluru Urban | E11: CNRB | F11: NORTH

Sheet Bank_Users
A1: user_id | B1: full_name | C1: role | D1: branch_id | E1: email | F1: mobile
A2: U-001 | B2: Demo User 001 | C2: BRANCH_USER | D2: BR-004 | E2: user001@demo-bank.in | F2: 9647525534
A3: U-002 | B3: Demo User 002 | C3: MAKER | D3: BR-002 | E3: user002@demo-bank.in | F3: 9283276483
A4: U-003 | B4: Demo User 003 | C4: BRANCH_USER | D4: BR-006 | E4: user003@demo-bank.in | F4: 9305641395
A5: U-004 | B5: Demo User 004 | C5: CHECKER | D5: BR-004 | E5: user004@demo-bank.in | F5: 9767242388
A6: U-005 | B6: Demo User 005 | C6: CHECKER | D6: BR-005 | E6: user005@demo-bank.in | F6: 9969653287
A7: U-006 | B7: Demo User 006 | C7: BRANCH_USER | D7: BR-002 | E7: user006@demo-bank.in | F7: 9122691669
A8: U-007 | B8: Demo User 007 | C8: MAKER | D8: BR-008 | E8: user007@demo-bank.in | F8: 9480184514
A9: U-008 | B9: Demo User 008 | C9: HO_USER | D9: BR-007 | E9: user008@demo-bank.in | F9: 9704828148
A10: U-009 | B10: Demo User 009 | C10: HO_USER | D10: BR-010 | E10: user009@demo-bank.in | F10: 9252880957
A11: U-010 | B11: Demo User 010 | C11: BRANCH_USER | D11: BR-001 | E11: user010@demo-bank.in | F11: 9543039117
A12: U-011 | B12: Demo User 011 | C12: MAKER | D12: BR-002 | E12: user011@demo-bank.in | F12: 9227824896
... A21: U-020 | B21: Demo User 020 | C21: NODAL_OFFICER | D21: BR-005 | E21: user020@demo-bank.in | F21: 9872343098

Sheet Demo_Scenarios
A1: scenario | B1: description
A2: HOLD_PLACED | B2: Successful lien/hold placed; status_code 20000; response_code 00
A3: NEGATIVE_LIEN | B3: Balance not available; negative lien marked; status_code 20010; response_code 00
A4: PARTIAL_HOLD | B4: Partial amount held; status_code 20005; response_code 00
A5: ACCOUNT_NOT_FOUND | B5: Invalid beneficiary details; status_code 40001; response_code 00
A6: DEPENDENCY_TIMEOUT | B6: CBS/rail timeout; status_code 50001; I4C response_code 99 (demo failure)
